[2022-12-08 16:25:19,060] {taskinstance.py:1159} INFO - Dependencies all met for <TaskInstance: move_data_from_s3_to_redshidt_with_awswrangler.move_data_from_s3_to_redshift manual__2022-12-08T16:25:10.604750+00:00 [queued]>
[2022-12-08 16:25:19,066] {taskinstance.py:1159} INFO - Dependencies all met for <TaskInstance: move_data_from_s3_to_redshidt_with_awswrangler.move_data_from_s3_to_redshift manual__2022-12-08T16:25:10.604750+00:00 [queued]>
[2022-12-08 16:25:19,066] {taskinstance.py:1356} INFO - 
--------------------------------------------------------------------------------
[2022-12-08 16:25:19,066] {taskinstance.py:1357} INFO - Starting attempt 2 of 2
[2022-12-08 16:25:19,066] {taskinstance.py:1358} INFO - 
--------------------------------------------------------------------------------
[2022-12-08 16:25:19,076] {taskinstance.py:1377} INFO - Executing <Task(PythonOperator): move_data_from_s3_to_redshift> on 2022-12-08 16:25:10.604750+00:00
[2022-12-08 16:25:19,080] {standard_task_runner.py:52} INFO - Started process 560 to run task
[2022-12-08 16:25:19,083] {standard_task_runner.py:79} INFO - Running: ['***', 'tasks', 'run', 'move_data_from_s3_to_redshidt_with_awswrangler', 'move_data_from_s3_to_redshift', 'manual__2022-12-08T16:25:10.604750+00:00', '--job-id', '97', '--raw', '--subdir', 'DAGS_FOLDER/move_data_s3redshift.py', '--cfg-path', '/tmp/tmph7fpgoqv', '--error-file', '/tmp/tmpmmuo0mrw']
[2022-12-08 16:25:19,084] {standard_task_runner.py:80} INFO - Job 97: Subtask move_data_from_s3_to_redshift
[2022-12-08 16:25:19,119] {task_command.py:369} INFO - Running <TaskInstance: move_data_from_s3_to_redshidt_with_awswrangler.move_data_from_s3_to_redshift manual__2022-12-08T16:25:10.604750+00:00 [running]> on host 8458a2c1ba2e
[2022-12-08 16:25:19,172] {taskinstance.py:1571} INFO - Exporting the following env vars:
AIRFLOW_CTX_DAG_OWNER=***
AIRFLOW_CTX_DAG_ID=move_data_from_s3_to_redshidt_with_awswrangler
AIRFLOW_CTX_TASK_ID=move_data_from_s3_to_redshift
AIRFLOW_CTX_EXECUTION_DATE=2022-12-08T16:25:10.604750+00:00
AIRFLOW_CTX_TRY_NUMBER=2
AIRFLOW_CTX_DAG_RUN_ID=manual__2022-12-08T16:25:10.604750+00:00
[2022-12-08 16:25:19,184] {credentials.py:1120} INFO - Found credentials in environment variables.
[2022-12-08 16:25:19,275] {taskinstance.py:1889} ERROR - Task failed with exception
Traceback (most recent call last):
  File "/home/airflow/.local/lib/python3.7/site-packages/airflow/operators/python.py", line 171, in execute
    return_value = self.execute_callable()
  File "/home/airflow/.local/lib/python3.7/site-packages/airflow/operators/python.py", line 189, in execute_callable
    return self.python_callable(*self.op_args, **self.op_kwargs)
  File "/opt/airflow/dags/move_data_s3redshift.py", line 21, in read_from_s3_and_insert_redshift
    s3_data = wr.s3.read_parquet(path=s3_path)
  File "/home/airflow/.local/lib/python3.7/site-packages/awswrangler/s3/_read_parquet.py", line 751, in read_parquet
    raise exceptions.NoFilesFound(f"No files Found on: {path}.")
awswrangler.exceptions.NoFilesFound: No files Found on: s3://***-jkimera-bucket/from_red.parquet.
[2022-12-08 16:25:19,301] {taskinstance.py:1400} INFO - Marking task as FAILED. dag_id=move_data_from_s3_to_redshidt_with_awswrangler, task_id=move_data_from_s3_to_redshift, execution_date=20221208T162510, start_date=20221208T162519, end_date=20221208T162519
[2022-12-08 16:25:19,309] {standard_task_runner.py:97} ERROR - Failed to execute job 97 for task move_data_from_s3_to_redshift (No files Found on: s3://***-jkimera-bucket/from_red.parquet.; 560)
[2022-12-08 16:25:19,334] {local_task_job.py:156} INFO - Task exited with return code 1
[2022-12-08 16:25:19,366] {local_task_job.py:273} INFO - 0 downstream tasks scheduled from follow-on schedule check
