[2022-12-04 20:23:15,234] {taskinstance.py:1159} INFO - Dependencies all met for <TaskInstance: third_test_s3_file_sensor.s3_file_check manual__2022-12-04T20:12:38.835562+00:00 [queued]>
[2022-12-04 20:23:15,240] {taskinstance.py:1159} INFO - Dependencies all met for <TaskInstance: third_test_s3_file_sensor.s3_file_check manual__2022-12-04T20:12:38.835562+00:00 [queued]>
[2022-12-04 20:23:15,241] {taskinstance.py:1356} INFO - 
--------------------------------------------------------------------------------
[2022-12-04 20:23:15,241] {taskinstance.py:1357} INFO - Starting attempt 3 of 3
[2022-12-04 20:23:15,241] {taskinstance.py:1358} INFO - 
--------------------------------------------------------------------------------
[2022-12-04 20:23:15,250] {taskinstance.py:1377} INFO - Executing <Task(S3KeySensor): s3_file_check> on 2022-12-04 20:12:38.835562+00:00
[2022-12-04 20:23:15,255] {standard_task_runner.py:52} INFO - Started process 321 to run task
[2022-12-04 20:23:15,258] {standard_task_runner.py:79} INFO - Running: ['***', 'tasks', 'run', 'third_test_s3_file_sensor', 's3_file_check', 'manual__2022-12-04T20:12:38.835562+00:00', '--job-id', '39', '--raw', '--subdir', 'DAGS_FOLDER/s3_file_sensor2.py', '--cfg-path', '/tmp/tmpz39yqar9', '--error-file', '/tmp/tmpytiowlqs']
[2022-12-04 20:23:15,259] {standard_task_runner.py:80} INFO - Job 39: Subtask s3_file_check
[2022-12-04 20:23:15,295] {task_command.py:369} INFO - Running <TaskInstance: third_test_s3_file_sensor.s3_file_check manual__2022-12-04T20:12:38.835562+00:00 [running]> on host 12cf17d16345
[2022-12-04 20:23:15,348] {taskinstance.py:1571} INFO - Exporting the following env vars:
AIRFLOW_CTX_DAG_EMAIL=nic@enye.tech
AIRFLOW_CTX_DAG_OWNER=***
AIRFLOW_CTX_DAG_ID=third_test_s3_file_sensor
AIRFLOW_CTX_TASK_ID=s3_file_check
AIRFLOW_CTX_EXECUTION_DATE=2022-12-04T20:12:38.835562+00:00
AIRFLOW_CTX_TRY_NUMBER=3
AIRFLOW_CTX_DAG_RUN_ID=manual__2022-12-04T20:12:38.835562+00:00
[2022-12-04 20:23:15,349] {s3.py:98} INFO - Poking for key : s3://***-jkimera-bucket/green_tripdata_2021-01.parquet
[2022-12-04 20:23:15,355] {base.py:68} INFO - Using connection ID 's3_conn' for task execution.
[2022-12-04 20:23:15,356] {base_aws.py:206} INFO - Credentials retrieved from login
[2022-12-04 20:23:15,478] {taskinstance.py:1889} ERROR - Task failed with exception
Traceback (most recent call last):
  File "/home/airflow/.local/lib/python3.7/site-packages/airflow/sensors/base.py", line 277, in execute
    poke_return = self.poke(context)
  File "/home/airflow/.local/lib/python3.7/site-packages/airflow/providers/amazon/aws/sensors/s3.py", line 101, in poke
    return self.get_hook().check_for_key(self.bucket_key, self.bucket_name)
  File "/home/airflow/.local/lib/python3.7/site-packages/airflow/providers/amazon/aws/hooks/s3.py", line 63, in wrapper
    return func(*bound_args.args, **bound_args.kwargs)
  File "/home/airflow/.local/lib/python3.7/site-packages/airflow/providers/amazon/aws/hooks/s3.py", line 91, in wrapper
    return func(*bound_args.args, **bound_args.kwargs)
  File "/home/airflow/.local/lib/python3.7/site-packages/airflow/providers/amazon/aws/hooks/s3.py", line 369, in check_for_key
    raise e
  File "/home/airflow/.local/lib/python3.7/site-packages/airflow/providers/amazon/aws/hooks/s3.py", line 363, in check_for_key
    self.get_conn().head_object(Bucket=bucket_name, Key=key)
  File "/home/airflow/.local/lib/python3.7/site-packages/botocore/client.py", line 415, in _api_call
    return self._make_api_call(operation_name, kwargs)
  File "/home/airflow/.local/lib/python3.7/site-packages/botocore/client.py", line 745, in _make_api_call
    raise error_class(parsed_response, operation_name)
botocore.exceptions.ClientError: An error occurred (403) when calling the HeadObject operation: Forbidden
[2022-12-04 20:23:15,485] {taskinstance.py:1400} INFO - Marking task as FAILED. dag_id=third_test_s3_file_sensor, task_id=s3_file_check, execution_date=20221204T201238, start_date=20221204T202315, end_date=20221204T202315
[2022-12-04 20:23:15,492] {standard_task_runner.py:97} ERROR - Failed to execute job 39 for task s3_file_check (An error occurred (403) when calling the HeadObject operation: Forbidden; 321)
[2022-12-04 20:23:15,510] {local_task_job.py:156} INFO - Task exited with return code 1
[2022-12-04 20:23:15,549] {local_task_job.py:273} INFO - 0 downstream tasks scheduled from follow-on schedule check
