[2022-12-04 20:23:15,219] {taskinstance.py:1159} INFO - Dependencies all met for <TaskInstance: third_test_s3_file_sensor.s3_file_check scheduled__2022-12-03T00:00:00+00:00 [queued]>
[2022-12-04 20:23:15,226] {taskinstance.py:1159} INFO - Dependencies all met for <TaskInstance: third_test_s3_file_sensor.s3_file_check scheduled__2022-12-03T00:00:00+00:00 [queued]>
[2022-12-04 20:23:15,226] {taskinstance.py:1356} INFO - 
--------------------------------------------------------------------------------
[2022-12-04 20:23:15,226] {taskinstance.py:1357} INFO - Starting attempt 3 of 3
[2022-12-04 20:23:15,226] {taskinstance.py:1358} INFO - 
--------------------------------------------------------------------------------
[2022-12-04 20:23:15,236] {taskinstance.py:1377} INFO - Executing <Task(S3KeySensor): s3_file_check> on 2022-12-03 00:00:00+00:00
[2022-12-04 20:23:15,241] {standard_task_runner.py:52} INFO - Started process 320 to run task
[2022-12-04 20:23:15,244] {standard_task_runner.py:79} INFO - Running: ['***', 'tasks', 'run', 'third_test_s3_file_sensor', 's3_file_check', 'scheduled__2022-12-03T00:00:00+00:00', '--job-id', '38', '--raw', '--subdir', 'DAGS_FOLDER/s3_file_sensor2.py', '--cfg-path', '/tmp/tmpywslvbxy', '--error-file', '/tmp/tmpq5kbppi_']
[2022-12-04 20:23:15,245] {standard_task_runner.py:80} INFO - Job 38: Subtask s3_file_check
[2022-12-04 20:23:15,254] {warnings.py:110} WARNING - /home/***/.local/lib/python3.7/site-packages/***/configuration.py:470: DeprecationWarning: The sql_alchemy_conn option in [core] has been moved to the sql_alchemy_conn option in [database] - the old setting has been used, but please update your config.
  option = self._get_environment_variables(deprecated_key, deprecated_section, key, section)

[2022-12-04 20:23:15,283] {task_command.py:369} INFO - Running <TaskInstance: third_test_s3_file_sensor.s3_file_check scheduled__2022-12-03T00:00:00+00:00 [running]> on host 12cf17d16345
[2022-12-04 20:23:15,338] {taskinstance.py:1571} INFO - Exporting the following env vars:
AIRFLOW_CTX_DAG_EMAIL=nic@enye.tech
AIRFLOW_CTX_DAG_OWNER=***
AIRFLOW_CTX_DAG_ID=third_test_s3_file_sensor
AIRFLOW_CTX_TASK_ID=s3_file_check
AIRFLOW_CTX_EXECUTION_DATE=2022-12-03T00:00:00+00:00
AIRFLOW_CTX_TRY_NUMBER=3
AIRFLOW_CTX_DAG_RUN_ID=scheduled__2022-12-03T00:00:00+00:00
[2022-12-04 20:23:15,338] {s3.py:98} INFO - Poking for key : s3://***-jkimera-bucket/green_tripdata_2021-01.parquet
[2022-12-04 20:23:15,345] {base.py:68} INFO - Using connection ID 's3_conn' for task execution.
[2022-12-04 20:23:15,345] {base_aws.py:206} INFO - Credentials retrieved from login
[2022-12-04 20:23:15,460] {taskinstance.py:1889} ERROR - Task failed with exception
Traceback (most recent call last):
  File "/home/airflow/.local/lib/python3.7/site-packages/airflow/sensors/base.py", line 277, in execute
    poke_return = self.poke(context)
  File "/home/airflow/.local/lib/python3.7/site-packages/airflow/providers/amazon/aws/sensors/s3.py", line 101, in poke
    return self.get_hook().check_for_key(self.bucket_key, self.bucket_name)
  File "/home/airflow/.local/lib/python3.7/site-packages/airflow/providers/amazon/aws/hooks/s3.py", line 63, in wrapper
    return func(*bound_args.args, **bound_args.kwargs)
  File "/home/airflow/.local/lib/python3.7/site-packages/airflow/providers/amazon/aws/hooks/s3.py", line 91, in wrapper
    return func(*bound_args.args, **bound_args.kwargs)
  File "/home/airflow/.local/lib/python3.7/site-packages/airflow/providers/amazon/aws/hooks/s3.py", line 369, in check_for_key
    raise e
  File "/home/airflow/.local/lib/python3.7/site-packages/airflow/providers/amazon/aws/hooks/s3.py", line 363, in check_for_key
    self.get_conn().head_object(Bucket=bucket_name, Key=key)
  File "/home/airflow/.local/lib/python3.7/site-packages/botocore/client.py", line 415, in _api_call
    return self._make_api_call(operation_name, kwargs)
  File "/home/airflow/.local/lib/python3.7/site-packages/botocore/client.py", line 745, in _make_api_call
    raise error_class(parsed_response, operation_name)
botocore.exceptions.ClientError: An error occurred (403) when calling the HeadObject operation: Forbidden
[2022-12-04 20:23:15,468] {taskinstance.py:1400} INFO - Marking task as FAILED. dag_id=third_test_s3_file_sensor, task_id=s3_file_check, execution_date=20221203T000000, start_date=20221204T202315, end_date=20221204T202315
[2022-12-04 20:23:15,475] {standard_task_runner.py:97} ERROR - Failed to execute job 38 for task s3_file_check (An error occurred (403) when calling the HeadObject operation: Forbidden; 320)
[2022-12-04 20:23:15,495] {local_task_job.py:156} INFO - Task exited with return code 1
[2022-12-04 20:23:15,532] {local_task_job.py:273} INFO - 0 downstream tasks scheduled from follow-on schedule check
